        public void close() throws IOException
        {
            // stop the run loop.  this will result in closeInternal being called by the time join() finishes.
            run = false;
            interrupt();
            try
            {
                this.join();
            }
            catch (InterruptedException e)
            {
                throw new AssertionError(e);
            }

            if (lastException != null)
                throw lastException;
        }

